ERROR:root:Internal server error: [Errno 2] No such file or directory: 'private_key.edoi'
Traceback (most recent call last):
  File "C:\Users\Awesome Kuhn Family\Documents\Tristan\httpe\edoi\httpe_server.py", line 63, in _load_keys
    with open("private_key.edoi","r") as f:
FileNotFoundError: [Errno 2] No such file or directory: 'private_key.edoi'
Load keys error [Errno 2] No such file or directory: 'private_key.edoi'
Traceback (most recent call last):
  File "C:\Users\Awesome Kuhn Family\Documents\Tristan\httpe\edoi\httpe_server.py", line 63, in _load_keys
    with open("private_key.edoi","r") as f:
FileNotFoundError: [Errno 2] No such file or directory: 'private_key.edoi'

During handling of the above exception, another exception occurred:

Traceback (most recent call last):
  File "C:\Users\Awesome Kuhn Family\Documents\Tristan\httpe\edoi\main.py", line 3, in <module>
    server = Httpe(use_edoi_node=True,edoi_ip='127.0.0.1',edoi_port=5122,name="HTTPE")
  File "C:\Users\Awesome Kuhn Family\Documents\Tristan\httpe\edoi\httpe_server.py", line 32, in __init__
    self._load_keys()
  File "C:\Users\Awesome Kuhn Family\Documents\Tristan\httpe\edoi\httpe_server.py", line 85, in _load_keys
    raise Exception(e)
Exception: [Errno 2] No such file or directory: 'private_key.edoi'
