ERROR:    Exception in ASGI application
  + Exception Group Traceback (most recent call last):
  |   File "C:\Users\Admin\AppData\Local\Programs\Python\Python312\Lib\site-packages\starlette\_utils.py", line 76, in collapse_excgroups
  |     yield
  |   File "C:\Users\Admin\AppData\Local\Programs\Python\Python312\Lib\site-packages\starlette\middleware\base.py", line 177, in __call__
  |     async with anyio.create_task_group() as task_group:
  |   File "C:\Users\Admin\AppData\Local\Programs\Python\Python312\Lib\site-packages\anyio\_backends\_asyncio.py", line 772, in __aexit__
  |     raise BaseExceptionGroup(
  | ExceptionGroup: unhandled errors in a TaskGroup (1 sub-exception)
  +-+---------------- 1 ----------------
    | Traceback (most recent call last):
    |   File "C:\Users\Admin\AppData\Local\Programs\Python\Python312\Lib\site-packages\uvicorn\protocols\http\httptools_impl.py", line 409, in run_asgi
    |     result = await app(  # type: ignore[func-returns-value]
    |              ^^^^^^^^^^^^^^^^^^^^^^^^^^^^^^^^^^^^^^^^^^^^^^
    |   File "C:\Users\Admin\AppData\Local\Programs\Python\Python312\Lib\site-packages\uvicorn\middleware\proxy_headers.py", line 60, in __call__
    |     return await self.app(scope, receive, send)
    |            ^^^^^^^^^^^^^^^^^^^^^^^^^^^^^^^^^^^^
    |   File "C:\Users\Admin\AppData\Local\Programs\Python\Python312\Lib\site-packages\fastapi\applications.py", line 1054, in __call__
    |     await super().__call__(scope, receive, send)
    |   File "C:\Users\Admin\AppData\Local\Programs\Python\Python312\Lib\site-packages\starlette\applications.py", line 112, in __call__
    |     await self.middleware_stack(scope, receive, send)
    |   File "C:\Users\Admin\AppData\Local\Programs\Python\Python312\Lib\site-packages\starlette\middleware\errors.py", line 187, in __call__
    |     raise exc
    |   File "C:\Users\Admin\AppData\Local\Programs\Python\Python312\Lib\site-packages\starlette\middleware\errors.py", line 165, in __call__
    |     await self.app(scope, receive, _send)
    |   File "C:\Users\Admin\AppData\Local\Programs\Python\Python312\Lib\site-packages\starlette\middleware\base.py", line 176, in __call__
    |     with recv_stream, send_stream, collapse_excgroups():
    |   File "C:\Users\Admin\AppData\Local\Programs\Python\Python312\Lib\contextlib.py", line 158, in __exit__
    |     self.gen.throw(value)
    |   File "C:\Users\Admin\AppData\Local\Programs\Python\Python312\Lib\site-packages\starlette\_utils.py", line 82, in collapse_excgroups
    |     raise exc
    |   File "C:\Users\Admin\AppData\Local\Programs\Python\Python312\Lib\site-packages\starlette\middleware\base.py", line 178, in __call__
    |     response = await self.dispatch_func(request, call_next)
    |                ^^^^^^^^^^^^^^^^^^^^^^^^^^^^^^^^^^^^^^^^^^^^
    |   File "F:\httpe\server\httpe_server.py", line 144, in jwt_auth_middleware
    |     return await call_next(request)
    |            ^^^^^^^^^^^^^^^^^^^^^^^^
    |   File "C:\Users\Admin\AppData\Local\Programs\Python\Python312\Lib\site-packages\starlette\middleware\base.py", line 156, in call_next
    |     raise app_exc
    |   File "C:\Users\Admin\AppData\Local\Programs\Python\Python312\Lib\site-packages\starlette\middleware\base.py", line 141, in coro
    |     await self.app(scope, receive_or_disconnect, send_no_error)
    |   File "C:\Users\Admin\AppData\Local\Programs\Python\Python312\Lib\site-packages\starlette\middleware\exceptions.py", line 62, in __call__
    |     await wrap_app_handling_exceptions(self.app, conn)(scope, receive, send)
    |   File "C:\Users\Admin\AppData\Local\Programs\Python\Python312\Lib\site-packages\starlette\_exception_handler.py", line 53, in wrapped_app
    |     raise exc
    |   File "C:\Users\Admin\AppData\Local\Programs\Python\Python312\Lib\site-packages\starlette\_exception_handler.py", line 42, in wrapped_app
    |     await app(scope, receive, sender)
    |   File "C:\Users\Admin\AppData\Local\Programs\Python\Python312\Lib\site-packages\starlette\routing.py", line 714, in __call__
    |     await self.middleware_stack(scope, receive, send)
    |   File "C:\Users\Admin\AppData\Local\Programs\Python\Python312\Lib\site-packages\starlette\routing.py", line 734, in app
    |     await route.handle(scope, receive, send)
    |   File "C:\Users\Admin\AppData\Local\Programs\Python\Python312\Lib\site-packages\starlette\routing.py", line 288, in handle
    |     await self.app(scope, receive, send)
    |   File "C:\Users\Admin\AppData\Local\Programs\Python\Python312\Lib\site-packages\starlette\routing.py", line 76, in app
    |     await wrap_app_handling_exceptions(app, request)(scope, receive, send)
    |   File "C:\Users\Admin\AppData\Local\Programs\Python\Python312\Lib\site-packages\starlette\_exception_handler.py", line 53, in wrapped_app
    |     raise exc
    |   File "C:\Users\Admin\AppData\Local\Programs\Python\Python312\Lib\site-packages\starlette\_exception_handler.py", line 42, in wrapped_app
    |     await app(scope, receive, sender)
    |   File "C:\Users\Admin\AppData\Local\Programs\Python\Python312\Lib\site-packages\starlette\routing.py", line 73, in app
    |     response = await f(request)
    |                ^^^^^^^^^^^^^^^^
    |   File "C:\Users\Admin\AppData\Local\Programs\Python\Python312\Lib\site-packages\fastapi\routing.py", line 301, in app
    |     raw_response = await run_endpoint_function(
    |                    ^^^^^^^^^^^^^^^^^^^^^^^^^^^^
    |   File "C:\Users\Admin\AppData\Local\Programs\Python\Python312\Lib\site-packages\fastapi\routing.py", line 212, in run_endpoint_function
    |     return await dependant.call(**values)
    |            ^^^^^^^^^^^^^^^^^^^^^^^^^^^^^^
    |   File "F:\httpe\server\main.py", line 18, in login
    |     return await httpe_server.client_login(payload)
    |            ^^^^^^^^^^^^^^^^^^^^^^^^^^^^^^^^^^^^^^^^
    |   File "F:\httpe\server\httpe_server.py", line 95, in client_login
    |     current_user = await user.authenticate_user(db, username, password)
    |                    ^^^^^^^^^^^^^^^^^^^^^^^^^^^^^^^^^^^^^^^^^^^^^^^^^^^^
    |   File "F:\httpe\server\user.py", line 38, in authenticate_user
    |     user = await get_user_by_username(db, username)
    |            ^^^^^^^^^^^^^^^^^^^^^^^^^^^^^^^^^^^^^^^^
    |   File "F:\httpe\server\user.py", line 28, in get_user_by_username
    |     result = await db.execute(select(User).where(User.username == username))
    |                    ^^^^^^^^^^
    | AttributeError: 'Depends' object has no attribute 'execute'
    +------------------------------------

During handling of the above exception, another exception occurred:

Traceback (most recent call last):
  File "C:\Users\Admin\AppData\Local\Programs\Python\Python312\Lib\site-packages\uvicorn\protocols\http\httptools_impl.py", line 409, in run_asgi
    result = await app(  # type: ignore[func-returns-value]
             ^^^^^^^^^^^^^^^^^^^^^^^^^^^^^^^^^^^^^^^^^^^^^^
  File "C:\Users\Admin\AppData\Local\Programs\Python\Python312\Lib\site-packages\uvicorn\middleware\proxy_headers.py", line 60, in __call__
    return await self.app(scope, receive, send)
           ^^^^^^^^^^^^^^^^^^^^^^^^^^^^^^^^^^^^
  File "C:\Users\Admin\AppData\Local\Programs\Python\Python312\Lib\site-packages\fastapi\applications.py", line 1054, in __call__
    await super().__call__(scope, receive, send)
  File "C:\Users\Admin\AppData\Local\Programs\Python\Python312\Lib\site-packages\starlette\applications.py", line 112, in __call__
    await self.middleware_stack(scope, receive, send)
  File "C:\Users\Admin\AppData\Local\Programs\Python\Python312\Lib\site-packages\starlette\middleware\errors.py", line 187, in __call__
    raise exc
  File "C:\Users\Admin\AppData\Local\Programs\Python\Python312\Lib\site-packages\starlette\middleware\errors.py", line 165, in __call__
    await self.app(scope, receive, _send)
  File "C:\Users\Admin\AppData\Local\Programs\Python\Python312\Lib\site-packages\starlette\middleware\base.py", line 176, in __call__
    with recv_stream, send_stream, collapse_excgroups():
  File "C:\Users\Admin\AppData\Local\Programs\Python\Python312\Lib\contextlib.py", line 158, in __exit__
    self.gen.throw(value)
  File "C:\Users\Admin\AppData\Local\Programs\Python\Python312\Lib\site-packages\starlette\_utils.py", line 82, in collapse_excgroups
    raise exc
  File "C:\Users\Admin\AppData\Local\Programs\Python\Python312\Lib\site-packages\starlette\middleware\base.py", line 178, in __call__
    response = await self.dispatch_func(request, call_next)
               ^^^^^^^^^^^^^^^^^^^^^^^^^^^^^^^^^^^^^^^^^^^^
  File "F:\httpe\server\httpe_server.py", line 144, in jwt_auth_middleware
    return await call_next(request)
           ^^^^^^^^^^^^^^^^^^^^^^^^
  File "C:\Users\Admin\AppData\Local\Programs\Python\Python312\Lib\site-packages\starlette\middleware\base.py", line 156, in call_next
    raise app_exc
  File "C:\Users\Admin\AppData\Local\Programs\Python\Python312\Lib\site-packages\starlette\middleware\base.py", line 141, in coro
    await self.app(scope, receive_or_disconnect, send_no_error)
  File "C:\Users\Admin\AppData\Local\Programs\Python\Python312\Lib\site-packages\starlette\middleware\exceptions.py", line 62, in __call__
    await wrap_app_handling_exceptions(self.app, conn)(scope, receive, send)
  File "C:\Users\Admin\AppData\Local\Programs\Python\Python312\Lib\site-packages\starlette\_exception_handler.py", line 53, in wrapped_app
    raise exc
  File "C:\Users\Admin\AppData\Local\Programs\Python\Python312\Lib\site-packages\starlette\_exception_handler.py", line 42, in wrapped_app
    await app(scope, receive, sender)
  File "C:\Users\Admin\AppData\Local\Programs\Python\Python312\Lib\site-packages\starlette\routing.py", line 714, in __call__
    await self.middleware_stack(scope, receive, send)
  File "C:\Users\Admin\AppData\Local\Programs\Python\Python312\Lib\site-packages\starlette\routing.py", line 734, in app
    await route.handle(scope, receive, send)
  File "C:\Users\Admin\AppData\Local\Programs\Python\Python312\Lib\site-packages\starlette\routing.py", line 288, in handle
    await self.app(scope, receive, send)
  File "C:\Users\Admin\AppData\Local\Programs\Python\Python312\Lib\site-packages\starlette\routing.py", line 76, in app
    await wrap_app_handling_exceptions(app, request)(scope, receive, send)
  File "C:\Users\Admin\AppData\Local\Programs\Python\Python312\Lib\site-packages\starlette\_exception_handler.py", line 53, in wrapped_app
    raise exc
  File "C:\Users\Admin\AppData\Local\Programs\Python\Python312\Lib\site-packages\starlette\_exception_handler.py", line 42, in wrapped_app
    await app(scope, receive, sender)
  File "C:\Users\Admin\AppData\Local\Programs\Python\Python312\Lib\site-packages\starlette\routing.py", line 73, in app
    response = await f(request)
               ^^^^^^^^^^^^^^^^
  File "C:\Users\Admin\AppData\Local\Programs\Python\Python312\Lib\site-packages\fastapi\routing.py", line 301, in app
    raw_response = await run_endpoint_function(
                   ^^^^^^^^^^^^^^^^^^^^^^^^^^^^
  File "C:\Users\Admin\AppData\Local\Programs\Python\Python312\Lib\site-packages\fastapi\routing.py", line 212, in run_endpoint_function
    return await dependant.call(**values)
           ^^^^^^^^^^^^^^^^^^^^^^^^^^^^^^
  File "F:\httpe\server\main.py", line 18, in login
    return await httpe_server.client_login(payload)
           ^^^^^^^^^^^^^^^^^^^^^^^^^^^^^^^^^^^^^^^^
  File "F:\httpe\server\httpe_server.py", line 95, in client_login
    current_user = await user.authenticate_user(db, username, password)
                   ^^^^^^^^^^^^^^^^^^^^^^^^^^^^^^^^^^^^^^^^^^^^^^^^^^^^
  File "F:\httpe\server\user.py", line 38, in authenticate_user
    user = await get_user_by_username(db, username)
           ^^^^^^^^^^^^^^^^^^^^^^^^^^^^^^^^^^^^^^^^
  File "F:\httpe\server\user.py", line 28, in get_user_by_username
    result = await db.execute(select(User).where(User.username == username))
                   ^^^^^^^^^^
AttributeError: 'Depends' object has no attribute 'execute'


code:
async def client_login(payload: LoginPayload,db: user.AsyncSession = Depends(user.get_token_db)):
    # Access data like:
    print("this data")
    username_enc = payload.username
    password_enc = payload.password
    print(f"{username_enc}:{password_enc}")
    encrypted_aes_key = payload.aes_key
    pub_pem = payload.rsa_key
    decrypted_aes_key = keys.decrypt_aes_key_with_rsa_private(encrypted_aes_key,load_pem_key("server_private.pem", is_private=True))
    username = keys.decrypt_string_with_aes(decrypted_aes_key,username_enc)
    password = keys.decrypt_string_with_aes(decrypted_aes_key,password_enc)
    current_user = await user.authenticate_user(db, username, password)
    if not current_user:
        raise HTTPException(
            status_code=status.HTTP_401_UNAUTHORIZED,
            detail="Incorrect username or password"
        )
    keys.set_client_key(current_user.id,decrypted_aes_key)
    access_token = keys.create_access_token(data={"sub": username})
    aes_token_encrypt_key = Fernet.generate_key()
    # print(pub_pem)
    encrypted_aes_token_encrypt_key = keys.encrypt_aes_key_with_rsa_public(aes_token_encrypt_key,keys.load_public_key(pub_pem))
    token_data = {"access_token": access_token, "token_type": "bearer"}
    
    encrypted_token_data = keys.encrypt_for_url(token_data,aes_token_encrypt_key)
    return_data = {"encrypted_data":encrypted_token_data,"aes_key":encrypted_aes_token_encrypt_key}
    return Response(
    content=json.dumps(return_data).encode("utf-8"),
    media_type="application/octet-stream"
        )    # print(f"{username} {password}")




@app.post("/client-login")
async def login(payload:httpe_server.LoginPayload):
    print("server here")
    return await httpe_server.client_login(payload)
